[2024-08-22T11:54:11.599+0000] {local_task_job_runner.py:123} INFO - ::group::Pre task execution logs
[2024-08-22T11:54:11.626+0000] {taskinstance.py:2603} INFO - Dependencies all met for dep_context=non-requeueable deps ti=<TaskInstance: job_scraper.scrape_and_upload manual__2024-08-22T11:49:01.893868+00:00 [queued]>
[2024-08-22T11:54:11.634+0000] {taskinstance.py:2603} INFO - Dependencies all met for dep_context=requeueable deps ti=<TaskInstance: job_scraper.scrape_and_upload manual__2024-08-22T11:49:01.893868+00:00 [queued]>
[2024-08-22T11:54:11.635+0000] {taskinstance.py:2856} INFO - Starting attempt 2 of 2
[2024-08-22T11:54:11.648+0000] {taskinstance.py:2879} INFO - Executing <Task(PythonOperator): scrape_and_upload> on 2024-08-22 11:49:01.893868+00:00
[2024-08-22T11:54:11.652+0000] {standard_task_runner.py:72} INFO - Started process 176 to run task
[2024-08-22T11:54:11.654+0000] {standard_task_runner.py:104} INFO - Running: ['airflow', 'tasks', 'run', 'job_scraper', 'scrape_and_upload', 'manual__2024-08-22T11:49:01.893868+00:00', '--job-id', '26', '--raw', '--subdir', 'DAGS_FOLDER/job_scraper_dag.py', '--cfg-path', '/tmp/tmprpyhlzco']
[2024-08-22T11:54:11.655+0000] {standard_task_runner.py:105} INFO - Job 26: Subtask scrape_and_upload
[2024-08-22T11:54:11.677+0000] {logging_mixin.py:190} WARNING - /home/airflow/.local/lib/python3.12/site-packages/airflow/settings.py:209 DeprecationWarning: The sql_alchemy_conn option in [core] has been moved to the sql_alchemy_conn option in [database] - the old setting has been used, but please update your config.
[2024-08-22T11:54:11.732+0000] {task_command.py:467} INFO - Running <TaskInstance: job_scraper.scrape_and_upload manual__2024-08-22T11:49:01.893868+00:00 [running]> on host c5b28d95d4ad
[2024-08-22T11:54:11.839+0000] {taskinstance.py:3122} INFO - Exporting env vars: AIRFLOW_CTX_DAG_OWNER='airflow' AIRFLOW_CTX_DAG_ID='job_scraper' AIRFLOW_CTX_TASK_ID='scrape_and_upload' AIRFLOW_CTX_EXECUTION_DATE='2024-08-22T11:49:01.893868+00:00' AIRFLOW_CTX_TRY_NUMBER='2' AIRFLOW_CTX_DAG_RUN_ID='manual__2024-08-22T11:49:01.893868+00:00'
[2024-08-22T11:54:11.840+0000] {taskinstance.py:731} INFO - ::endgroup::
[2024-08-22T11:54:12.427+0000] {taskinstance.py:3301} ERROR - Task failed with exception
Traceback (most recent call last):
  File "/home/airflow/.local/lib/python3.12/site-packages/serpapi/http.py", line 59, in raise_for_status
    r.raise_for_status()
  File "/home/airflow/.local/lib/python3.12/site-packages/requests/models.py", line 1024, in raise_for_status
    raise HTTPError(http_error_msg, response=self)
requests.exceptions.HTTPError: 401 Client Error: Unauthorized for url: https://serpapi.com/search?engine=google_jobs&q=data+engineer&location=Dhaka&api_key=65a170ad84895c39a99003aa0f033fe7def1f0c7

During handling of the above exception, another exception occurred:

Traceback (most recent call last):
  File "/home/airflow/.local/lib/python3.12/site-packages/serpapi/http.py", line 47, in request
    raise_for_status(r)
  File "/home/airflow/.local/lib/python3.12/site-packages/serpapi/http.py", line 61, in raise_for_status
    raise HTTPError(e)
serpapi.exceptions.HTTPError: 401 Client Error: Unauthorized for url: https://serpapi.com/search?engine=google_jobs&q=data+engineer&location=Dhaka&api_key=65a170ad84895c39a99003aa0f033fe7def1f0c7

During handling of the above exception, another exception occurred:

Traceback (most recent call last):
  File "/home/airflow/.local/lib/python3.12/site-packages/airflow/models/taskinstance.py", line 767, in _execute_task
    result = _execute_callable(context=context, **execute_callable_kwargs)
             ^^^^^^^^^^^^^^^^^^^^^^^^^^^^^^^^^^^^^^^^^^^^^^^^^^^^^^^^^^^^^
  File "/home/airflow/.local/lib/python3.12/site-packages/airflow/models/taskinstance.py", line 733, in _execute_callable
    return ExecutionCallableRunner(
           ^^^^^^^^^^^^^^^^^^^^^^^^
  File "/home/airflow/.local/lib/python3.12/site-packages/airflow/utils/operator_helpers.py", line 252, in run
    return self.func(*args, **kwargs)
           ^^^^^^^^^^^^^^^^^^^^^^^^^^
  File "/home/airflow/.local/lib/python3.12/site-packages/airflow/models/baseoperator.py", line 406, in wrapper
    return func(self, *args, **kwargs)
           ^^^^^^^^^^^^^^^^^^^^^^^^^^^
  File "/home/airflow/.local/lib/python3.12/site-packages/airflow/operators/python.py", line 238, in execute
    return_value = self.execute_callable()
                   ^^^^^^^^^^^^^^^^^^^^^^^
  File "/home/airflow/.local/lib/python3.12/site-packages/airflow/operators/python.py", line 256, in execute_callable
    return runner.run(*self.op_args, **self.op_kwargs)
           ^^^^^^^^^^^^^^^^^^^^^^^^^^^^^^^^^^^^^^^^^^^
  File "/home/airflow/.local/lib/python3.12/site-packages/airflow/utils/operator_helpers.py", line 252, in run
    return self.func(*args, **kwargs)
           ^^^^^^^^^^^^^^^^^^^^^^^^^^
  File "/opt/airflow/dags/job_scraper_dag.py", line 30, in run_scraper_and_upload
    jobs = scrape_jobs()
           ^^^^^^^^^^^^^
  File "/opt/airflow/scripts/scraper.py", line 36, in scrape_jobs
    job_data = fetch_jobs_from_serpapi()
               ^^^^^^^^^^^^^^^^^^^^^^^^^
  File "/opt/airflow/scripts/scraper.py", line 26, in fetch_jobs_from_serpapi
    results = client.search(params)
              ^^^^^^^^^^^^^^^^^^^^^
  File "/home/airflow/.local/lib/python3.12/site-packages/serpapi/core.py", line 66, in search
    r = self.request("GET", "/search", params=params)
        ^^^^^^^^^^^^^^^^^^^^^^^^^^^^^^^^^^^^^^^^^^^^^
  File "/home/airflow/.local/lib/python3.12/site-packages/serpapi/http.py", line 49, in request
    raise HTTPError(e)
serpapi.exceptions.HTTPError: 401 Client Error: Unauthorized for url: https://serpapi.com/search?engine=google_jobs&q=data+engineer&location=Dhaka&api_key=65a170ad84895c39a99003aa0f033fe7def1f0c7
[2024-08-22T11:54:12.455+0000] {taskinstance.py:1225} INFO - Marking task as FAILED. dag_id=job_scraper, task_id=scrape_and_upload, run_id=manual__2024-08-22T11:49:01.893868+00:00, execution_date=20240822T114901, start_date=20240822T115411, end_date=20240822T115412
[2024-08-22T11:54:12.475+0000] {taskinstance.py:340} INFO - ::group::Post task execution logs
[2024-08-22T11:54:12.475+0000] {standard_task_runner.py:124} ERROR - Failed to execute job 26 for task scrape_and_upload (401 Client Error: Unauthorized for url: https://serpapi.com/search?engine=google_jobs&q=data+engineer&location=Dhaka&api_key=65a170ad84895c39a99003aa0f033fe7def1f0c7; 176)
Traceback (most recent call last):
  File "/home/airflow/.local/lib/python3.12/site-packages/serpapi/http.py", line 59, in raise_for_status
    r.raise_for_status()
  File "/home/airflow/.local/lib/python3.12/site-packages/requests/models.py", line 1024, in raise_for_status
    raise HTTPError(http_error_msg, response=self)
requests.exceptions.HTTPError: 401 Client Error: Unauthorized for url: https://serpapi.com/search?engine=google_jobs&q=data+engineer&location=Dhaka&api_key=65a170ad84895c39a99003aa0f033fe7def1f0c7

During handling of the above exception, another exception occurred:

Traceback (most recent call last):
  File "/home/airflow/.local/lib/python3.12/site-packages/serpapi/http.py", line 47, in request
    raise_for_status(r)
  File "/home/airflow/.local/lib/python3.12/site-packages/serpapi/http.py", line 61, in raise_for_status
    raise HTTPError(e)
serpapi.exceptions.HTTPError: 401 Client Error: Unauthorized for url: https://serpapi.com/search?engine=google_jobs&q=data+engineer&location=Dhaka&api_key=65a170ad84895c39a99003aa0f033fe7def1f0c7

During handling of the above exception, another exception occurred:

Traceback (most recent call last):
  File "/home/airflow/.local/lib/python3.12/site-packages/airflow/task/task_runner/standard_task_runner.py", line 117, in _start_by_fork
    ret = args.func(args, dag=self.dag)
          ^^^^^^^^^^^^^^^^^^^^^^^^^^^^^
  File "/home/airflow/.local/lib/python3.12/site-packages/airflow/cli/cli_config.py", line 49, in command
    return func(*args, **kwargs)
           ^^^^^^^^^^^^^^^^^^^^^
  File "/home/airflow/.local/lib/python3.12/site-packages/airflow/utils/cli.py", line 115, in wrapper
    return f(*args, **kwargs)
           ^^^^^^^^^^^^^^^^^^
  File "/home/airflow/.local/lib/python3.12/site-packages/airflow/cli/commands/task_command.py", line 483, in task_run
    task_return_code = _run_task_by_selected_method(args, _dag, ti)
                       ^^^^^^^^^^^^^^^^^^^^^^^^^^^^^^^^^^^^^^^^^^^^
  File "/home/airflow/.local/lib/python3.12/site-packages/airflow/cli/commands/task_command.py", line 256, in _run_task_by_selected_method
    return _run_raw_task(args, ti)
           ^^^^^^^^^^^^^^^^^^^^^^^
  File "/home/airflow/.local/lib/python3.12/site-packages/airflow/cli/commands/task_command.py", line 341, in _run_raw_task
    return ti._run_raw_task(
           ^^^^^^^^^^^^^^^^^
  File "/home/airflow/.local/lib/python3.12/site-packages/airflow/utils/session.py", line 97, in wrapper
    return func(*args, session=session, **kwargs)
           ^^^^^^^^^^^^^^^^^^^^^^^^^^^^^^^^^^^^^^
  File "/home/airflow/.local/lib/python3.12/site-packages/airflow/models/taskinstance.py", line 2995, in _run_raw_task
    return _run_raw_task(
           ^^^^^^^^^^^^^^
  File "/home/airflow/.local/lib/python3.12/site-packages/airflow/models/taskinstance.py", line 273, in _run_raw_task
    TaskInstance._execute_task_with_callbacks(
  File "/home/airflow/.local/lib/python3.12/site-packages/airflow/models/taskinstance.py", line 3149, in _execute_task_with_callbacks
    result = self._execute_task(context, task_orig)
             ^^^^^^^^^^^^^^^^^^^^^^^^^^^^^^^^^^^^^^
  File "/home/airflow/.local/lib/python3.12/site-packages/airflow/models/taskinstance.py", line 3173, in _execute_task
    return _execute_task(self, context, task_orig)
           ^^^^^^^^^^^^^^^^^^^^^^^^^^^^^^^^^^^^^^^
  File "/home/airflow/.local/lib/python3.12/site-packages/airflow/models/taskinstance.py", line 767, in _execute_task
    result = _execute_callable(context=context, **execute_callable_kwargs)
             ^^^^^^^^^^^^^^^^^^^^^^^^^^^^^^^^^^^^^^^^^^^^^^^^^^^^^^^^^^^^^
  File "/home/airflow/.local/lib/python3.12/site-packages/airflow/models/taskinstance.py", line 733, in _execute_callable
    return ExecutionCallableRunner(
           ^^^^^^^^^^^^^^^^^^^^^^^^
  File "/home/airflow/.local/lib/python3.12/site-packages/airflow/utils/operator_helpers.py", line 252, in run
    return self.func(*args, **kwargs)
           ^^^^^^^^^^^^^^^^^^^^^^^^^^
  File "/home/airflow/.local/lib/python3.12/site-packages/airflow/models/baseoperator.py", line 406, in wrapper
    return func(self, *args, **kwargs)
           ^^^^^^^^^^^^^^^^^^^^^^^^^^^
  File "/home/airflow/.local/lib/python3.12/site-packages/airflow/operators/python.py", line 238, in execute
    return_value = self.execute_callable()
                   ^^^^^^^^^^^^^^^^^^^^^^^
  File "/home/airflow/.local/lib/python3.12/site-packages/airflow/operators/python.py", line 256, in execute_callable
    return runner.run(*self.op_args, **self.op_kwargs)
           ^^^^^^^^^^^^^^^^^^^^^^^^^^^^^^^^^^^^^^^^^^^
  File "/home/airflow/.local/lib/python3.12/site-packages/airflow/utils/operator_helpers.py", line 252, in run
    return self.func(*args, **kwargs)
           ^^^^^^^^^^^^^^^^^^^^^^^^^^
  File "/opt/airflow/dags/job_scraper_dag.py", line 30, in run_scraper_and_upload
    jobs = scrape_jobs()
           ^^^^^^^^^^^^^
  File "/opt/airflow/scripts/scraper.py", line 36, in scrape_jobs
    job_data = fetch_jobs_from_serpapi()
               ^^^^^^^^^^^^^^^^^^^^^^^^^
  File "/opt/airflow/scripts/scraper.py", line 26, in fetch_jobs_from_serpapi
    results = client.search(params)
              ^^^^^^^^^^^^^^^^^^^^^
  File "/home/airflow/.local/lib/python3.12/site-packages/serpapi/core.py", line 66, in search
    r = self.request("GET", "/search", params=params)
        ^^^^^^^^^^^^^^^^^^^^^^^^^^^^^^^^^^^^^^^^^^^^^
  File "/home/airflow/.local/lib/python3.12/site-packages/serpapi/http.py", line 49, in request
    raise HTTPError(e)
serpapi.exceptions.HTTPError: 401 Client Error: Unauthorized for url: https://serpapi.com/search?engine=google_jobs&q=data+engineer&location=Dhaka&api_key=65a170ad84895c39a99003aa0f033fe7def1f0c7
[2024-08-22T11:54:12.510+0000] {local_task_job_runner.py:261} INFO - Task exited with return code 1
[2024-08-22T11:54:12.540+0000] {taskinstance.py:3891} INFO - 0 downstream tasks scheduled from follow-on schedule check
[2024-08-22T11:54:12.543+0000] {local_task_job_runner.py:240} INFO - ::endgroup::
